<?xml version="1.0"?>
<robot name="Farmbeast" xmlns:xacro="http://www.ros.org/wiki/xacro" >

    <xacro:include filename="$(find farmbeast_simulation)/urdf/include/inertial_macros.xacro"/>



    <material name="white">
        <color rgba="1 1 1 1" />
    </material>

    <material name="orange">
        <color rgba="1 0.3 0.1 1"/>
    </material>

    <material name="blue">
        <color rgba="0.2 0.2 1 1"/>
    </material>

    <material name="black">
        <color rgba="0 0 0 1"/>
    </material>

    <!-- BASE LINK -->

    <link name="base_link">
    </link>


    <!-- CHASSIS LINK -->

    <joint name="chassis_joint" type="fixed">
        <parent link="base_link"/>
        <child link="chassis"/>
        <origin xyz="0 0 0.15"/>
    </joint>

    <link name="chassis">
        <visual>
            <origin xyz="0 0 0"/>
            <geometry>
                <box size="0.5 0.5 0.3"/>
            </geometry>
            <material name="white"/>
        </visual>
        <collision>
            <origin xyz="0 0 0"/>
            <geometry>
                <box size="0.5 0.5 0.3"/>
            </geometry>
        </collision>
        <xacro:inertial_box mass="2" x="0.5" y="0.5" z="0.3">
            <origin xyz="0 0 0" rpy="0 0 0"/>
        </xacro:inertial_box>
    </link>

    <gazebo reference="chassis">
        <material>Gazebo/White</material>
    </gazebo>

    <!-- Left front z axis -->
    <joint name="left_front_z_axis_joint" type="revolute">
        <parent link="base_link"/>
        <child link="left_front_z_axis"/>
        <origin xyz="0.2 0.3 0" rpy="0 0 0" />
        <axis xyz="0 0 1"/>
        <limit lower="-0.9" upper="0.9" effort="1" velocity="5"/>
    </joint>
    <link name="left_front_z_axis">
        <visual>
            <geometry>
                <cylinder radius="0.03" length="0.1"/>
            </geometry>
            <material name="orange"/>
        </visual>
        <collision>
            <geometry>
               <cylinder radius="0.03" length="0.1"/>
            </geometry>
        </collision>
        <xacro:inertial_cylinder mass="0.1" length="0.06" radius="0.02">
            <origin xyz="0 0 0" rpy="0 0 0"/>
        </xacro:inertial_cylinder>
    </link>

    <transmission name="left_front_z_axis_trans">
      <type>transmission_interface/SimpleTransmission</type>
      <joint name="left_front_z_axis_joint">
        <hardwareInterface>hardware_interface/PositionJointInterface</hardwareInterface>
      </joint>
      <actuator name="left_front_z_axis_actuator">
        <mechanicalReduction>1</mechanicalReduction>
      </actuator>
    </transmission>

    <gazebo reference="left_front_z_axis">
        <material>Gazebo/Orange</material>
    </gazebo>
    <!-- left front wheel -->

    <joint name="left_front_wheel_joint" type="continuous">
        <parent link="left_front_z_axis"/>
        <child link="left_front_wheel"/>
        <origin xyz="0 0.06 -0.05" rpy="-${pi/2} 0 0" />
        <axis xyz="0 0 1"/>
    </joint>

    <link name="left_front_wheel">
        <visual>
            <geometry>
                <cylinder radius="0.1" length="0.04"/>
            </geometry>
            <material name="blue"/>
        </visual>
        <collision>
            <geometry>
                <cylinder radius="0.1" length="0.04"/>
            </geometry>
        </collision>
        <xacro:inertial_cylinder mass="0.1" length="0.04" radius="0.05">
            <origin xyz="0 0 0" rpy="0 0 0"/>
        </xacro:inertial_cylinder>
    </link>
    
    <transmission name="left_front_wheel_trans">
      <type>transmission_interface/SimpleTransmission</type>
      <joint name="left_front_wheel_joint">
        <hardwareInterface>hardware_interface/VelocityJointInterface</hardwareInterface>
      </joint>
      <actuator name="left_front_wheel_actuator">
        <mechanicalReduction>1</mechanicalReduction>
      </actuator>
    </transmission>

    <gazebo reference="left_front_wheel">
        <material>Gazebo/Blue</material>
        <mu1 value="200"/>
        <mu2 value="100"/>
    </gazebo>

    <!-- Left back z axis -->
    <joint name="left_back_z_axis_joint" type="revolute">
        <parent link="base_link"/>
        <child link="left_back_z_axis"/>
        <origin xyz="-0.2 0.3 0" rpy="0 0 0" />
        <axis xyz="0 0 1"/>
        <limit lower="-0.9" upper="0.9" effort="1" velocity="5"/>
    </joint>
    <link name="left_back_z_axis">
        <visual>
            <geometry>
                <cylinder radius="0.03" length="0.1"/>
            </geometry>
            <material name="orange"/>
        </visual>
        <collision>
            <geometry>
               <cylinder radius="0.03" length="0.1"/>
            </geometry>
        </collision>
        <xacro:inertial_cylinder mass="0.1" length="0.06" radius="0.02">
            <origin xyz="0 0 0" rpy="0 0 0"/>
        </xacro:inertial_cylinder>
    </link>

    <transmission name="left_back_z_axis_trans">
      <type>transmission_interface/SimpleTransmission</type>
      <joint name="left_back_z_axis_joint">
        <hardwareInterface>hardware_interface/PositionJointInterface</hardwareInterface>
      </joint>
      <actuator name="left_back_z_axis_actuator">
        <mechanicalReduction>1</mechanicalReduction>
      </actuator>
    </transmission>

    <gazebo reference="left_back_z_axis">
        <material>Gazebo/Orange</material>
    </gazebo>

    <!-- left back wheel -->

    <joint name="left_back_wheel_joint" type="continuous">
        <parent link="left_back_z_axis"/>
        <child link="left_back_wheel"/>
        <origin xyz="0 0.06 -0.05" rpy="-${pi/2} 0 0" />
        <axis xyz="0 0 1"/>
    </joint>

    <link name="left_back_wheel">
        <visual>
            <geometry>
                <cylinder radius="0.1" length="0.04"/>
            </geometry>
            <material name="blue"/>
        </visual>
        <collision>
            <geometry>
                <cylinder radius="0.1" length="0.04"/>
            </geometry>
        </collision>
        <xacro:inertial_cylinder mass="0.1" length="0.04" radius="0.05">
            <origin xyz="0 0 0" rpy="0 0 0"/>
        </xacro:inertial_cylinder>
    </link>

    <transmission name="left_back_wheel_trans">
      <type>transmission_interface/SimpleTransmission</type>
      <joint name="left_back_wheel_joint">
        <hardwareInterface>hardware_interface/VelocityJointInterface</hardwareInterface>
      </joint>
      <actuator name="left_back_wheel_actuator">
        <mechanicalReduction>1</mechanicalReduction>
      </actuator>
    </transmission>
    
    <gazebo reference="left_back_wheel">
        <material>Gazebo/Blue</material>
        <mu1 value="200"/>
        <mu2 value="100"/>
    </gazebo>


    <!-- right front z axis -->
    <joint name="right_front_z_axis_joint" type="revolute">
        <parent link="base_link"/>
        <child link="right_front_z_axis"/>
        <origin xyz="0.2 -0.3 0" rpy="0 0 0" />
        <axis xyz="0 0 1"/>
        <limit lower="-0.9" upper="0.9" effort="1" velocity="5"/>
    </joint>
    <link name="right_front_z_axis">
        <visual>
            <geometry>
                <cylinder radius="0.03" length="0.1"/>
            </geometry>
            <material name="orange"/>
        </visual>
        <collision>
            <geometry>
                <cylinder radius="0.03" length="0.1"/>
            </geometry>
        </collision>
        <xacro:inertial_cylinder mass="0.1" length="0.06" radius="0.02">
            <origin xyz="0 0 0" rpy="0 0 0"/>
        </xacro:inertial_cylinder>
    </link>

    <transmission name="right_front_z_axis_trans">
      <type>transmission_interface/SimpleTransmission</type>
      <joint name="right_front_z_axis_joint">
        <hardwareInterface>hardware_interface/PositionJointInterface</hardwareInterface>
      </joint>
      <actuator name="right_front_z_axis_actuator">
        <mechanicalReduction>1</mechanicalReduction>
      </actuator>
    </transmission>    

    <gazebo reference="right_front_z_axis">
        <material>Gazebo/Orange</material>
    </gazebo>

    <!-- right front wheel -->

    <joint name="right_front_wheel_joint" type="continuous">
        <parent link="right_front_z_axis"/>
        <child link="right_front_wheel"/>
        <origin xyz="0 -0.06 -0.05" rpy="-${pi/2} 0 0" />
        <axis xyz="0 0 1"/>
    </joint>

    <link name="right_front_wheel">
        <visual>
            <geometry>
                <cylinder radius="0.1" length="0.04"/>
            </geometry>
            <material name="blue"/>
        </visual>
        <collision>
            <geometry>
               <cylinder radius="0.1" length="0.04"/>
            </geometry>
        </collision>
        <xacro:inertial_cylinder mass="0.1" length="0.04" radius="0.05">
            <origin xyz="0 0 0" rpy="0 0 0"/>
        </xacro:inertial_cylinder>
    </link>

    <transmission name="right_front_wheel_trans">
      <type>transmission_interface/SimpleTransmission</type>
      <joint name="right_front_wheel_joint">
        <hardwareInterface>hardware_interface/VelocityJointInterface</hardwareInterface>
      </joint>
      <actuator name="right_front_wheel_actuator">
        <mechanicalReduction>1</mechanicalReduction>
      </actuator>
    </transmission>

    <gazebo reference="right_front_wheel">
        <material>Gazebo/Blue</material>
        <mu1 value="200"/>
        <mu2 value="100"/>
    </gazebo>

    <!-- right back z axis -->
    <joint name="right_back_z_axis_joint" type="revolute">
        <parent link="base_link"/>
        <child link="right_back_z_axis"/>
        <origin xyz="-0.2 -0.3 0" rpy="0 0 0" />
        <axis xyz="0 0 1"/>
        <limit lower="-0.9" upper="0.9" effort="1" velocity="5"/>
    </joint>
    <link name="right_back_z_axis">
        <visual>
            <geometry>
                <cylinder radius="0.03" length="0.1"/>
            </geometry>
            <material name="orange"/>
        </visual>
        <collision>
            <geometry>
                <cylinder radius="0.03" length="0.1"/>
            </geometry>
        </collision>
        <xacro:inertial_cylinder mass="0.1" length="0.06" radius="0.02">
            <origin xyz="0 0 0" rpy="0 0 0"/>
        </xacro:inertial_cylinder>
    </link>

    <transmission name="right_back_z_axis_trans">
      <type>transmission_interface/SimpleTransmission</type>
      <joint name="right_back_z_axis_joint">
        <hardwareInterface>hardware_interface/PositionJointInterface</hardwareInterface>
      </joint>
      <actuator name="right_back_z_axis_actuator">
        <mechanicalReduction>1</mechanicalReduction>
      </actuator>
    </transmission>

    <gazebo reference="right_back_z_axis">
        <material>Gazebo/Orange</material>
    </gazebo>

    <!-- right back wheel -->

    <joint name="right_back_wheel_joint" type="continuous">
        <parent link="right_back_z_axis"/>
        <child link="right_back_wheel"/>
        <origin xyz="0 -0.06 -0.05" rpy="-${pi/2} 0 0" />
        <axis xyz="0 0 1"/>
    </joint>

    <link name="right_back_wheel">
        <visual>
            <geometry>
                <cylinder radius="0.1" length="0.04"/>
            </geometry>
            <material name="blue"/>
        </visual>
        <collision>
            <geometry>
                <cylinder radius="0.1" length="0.04"/>
            </geometry>
        </collision>
        <xacro:inertial_cylinder mass="0.1" length="0.04" radius="0.05">
            <origin xyz="0 0 0" rpy="0 0 0"/>
        </xacro:inertial_cylinder>
    </link>

    <transmission name="right_back_wheel_trans">
      <type>transmission_interface/SimpleTransmission</type>
      <joint name="right_back_wheel_joint">
        <hardwareInterface>hardware_interface/VelocityJointInterface</hardwareInterface>
      </joint>
      <actuator name="right_back_wheel_actuator">
        <mechanicalReduction>1</mechanicalReduction>
      </actuator>
    </transmission>

    <gazebo reference="right_back_wheel">
        <material>Gazebo/Blue</material>
        <mu1 value="200"/>
        <mu2 value="100"/>
    </gazebo>

    <!-- ROS cotntroll-->
    <gazebo>
        <plugin name="gazebo_ros_control" filename="libgazebo_ros_control.so">
            <robotNamespace>/farmbeast</robotNamespace>
        </plugin>
    </gazebo>

    <!--Velodyne include-->
    <xacro:arg name="gpu" default="false"/>
    <xacro:property name="gpu" value="$(arg gpu)" />
    <xacro:arg name="organize_cloud" default="false"/>
    <xacro:property name="organize_cloud" value="$(arg organize_cloud)" />
    <xacro:include filename="$(find velodyne_description)/urdf/VLP-16.urdf.xacro"/>
    <xacro:VLP-16 parent="base_link" name="velodyne" topic="/velodyne_points" organize_cloud="${organize_cloud}" hz="10" samples="440" gpu="${gpu}" min_range="0.1" max_range="10.0" >
        <origin xyz="0.25 0 0.3" rpy="0 0.5 0" />
     </xacro:VLP-16>


</robot>