<?xml version="1.0"?>
<robot name="Farmbeast" xmlns:xacro="http://www.ros.org/wiki/xacro" >

    <xacro:include filename="$(find farmbeast_simulation)/urdf/include/inertial_macros.xacro"/>

    <material name="white">
        <color rgba="1 1 1 1" />
    </material>

    <material name="orange">
        <color rgba="1 0.3 0.1 1"/>
    </material>

    <material name="blue">
        <color rgba="0.2 0.2 1 1"/>
    </material>

    <material name="black">
        <color rgba="0 0 0 1"/>
    </material>

    <!-- BASE LINK -->

    <link name="base_link">
    </link>


    <!-- CHASSIS LINK -->

    <joint name="chassis_joint" type="fixed">
        <parent link="base_link"/>
        <child link="chassis"/>
        <origin xyz="0 0 0.15"/>
    </joint>

    <link name="chassis">
        <visual>
            <origin xyz="0 0 0"/>
            <geometry>
                <box size="0.5 0.5 0.3"/>
            </geometry>
            <material name="white"/>
        </visual>
        <collision>
            <origin xyz="0 0 0"/>
            <geometry>
                <box size="0.5 0.5 0.3"/>
            </geometry>
        </collision>
        <xacro:inertial_box mass="1" x="0.5" y="0.5" z="0.3">
            <origin xyz="0 0 0" rpy="0 0 0"/>
        </xacro:inertial_box>
    </link>

    <gazebo reference="chassis">
        <material>Gazebo/White</material>
    </gazebo>

    <!-- Left front z axis -->
    <joint name="left_front_z_axis_joint" type="revolute">
        <parent link="base_link"/>
        <child link="left_front_z_axis"/>
        <origin xyz="0.2 0.3 0" rpy="0 0 0" />
        <axis xyz="0 0 1"/>
        <limit lower="-0.9" upper="0.9" effort="1" velocity="5"/>
    </joint>
    <link name="left_front_z_axis">
        <visual>
            <geometry>
                <cylinder radius="0.03" length="0.1"/>
            </geometry>
            <material name="orange"/>
        </visual>
        <collision>
            <geometry>
                <cylinder radius="0.02" length="0.06"/>
            </geometry>
        </collision>
        <xacro:inertial_cylinder mass="0.1" length="0.06" radius="0.02">
            <origin xyz="0 0 0" rpy="0 0 0"/>
        </xacro:inertial_cylinder>
    </link>
    <!-- left front wheel -->

    <joint name="left_front_wheel_joint" type="continuous">
        <parent link="left_front_z_axis"/>
        <child link="left_front_wheel"/>
        <origin xyz="0 0.06 -0.05" rpy="-${pi/2} 0 0" />
        <axis xyz="0 0 1"/>
    </joint>

    <link name="left_front_wheel">
        <visual>
            <geometry>
                <cylinder radius="0.1" length="0.04"/>
            </geometry>
            <material name="blue"/>
        </visual>
        <collision>
            <geometry>
                <cylinder radius="0.05" length="0.04"/>
            </geometry>
        </collision>
        <xacro:inertial_cylinder mass="0.1" length="0.04" radius="0.05">
            <origin xyz="0 0 0" rpy="0 0 0"/>
        </xacro:inertial_cylinder>
    </link>

    <gazebo reference="left_wheel">
        <material>Gazebo/Blue</material>
    </gazebo>


<!-- Left back z axis -->
    <joint name="left_back_z_axis_joint" type="revolute">
        <parent link="base_link"/>
        <child link="left_back_z_axis"/>
        <origin xyz="-0.2 0.3 0" rpy="0 0 0" />
        <axis xyz="0 0 1"/>
        <limit lower="-0.9" upper="0.9" effort="1" velocity="5"/>
    </joint>
    <link name="left_back_z_axis">
        <visual>
            <geometry>
                <cylinder radius="0.03" length="0.1"/>
            </geometry>
            <material name="orange"/>
        </visual>
        <collision>
            <geometry>
                <cylinder radius="0.02" length="0.06"/>
            </geometry>
        </collision>
        <xacro:inertial_cylinder mass="0.1" length="0.06" radius="0.02">
            <origin xyz="0 0 0" rpy="0 0 0"/>
        </xacro:inertial_cylinder>
    </link>
    <!-- left back wheel -->

    <joint name="left_back_wheel_joint" type="continuous">
        <parent link="left_back_z_axis"/>
        <child link="left_back_wheel"/>
        <origin xyz="0 0.06 -0.05" rpy="-${pi/2} 0 0" />
        <axis xyz="0 0 1"/>
    </joint>

    <link name="left_back_wheel">
        <visual>
            <geometry>
                <cylinder radius="0.1" length="0.04"/>
            </geometry>
            <material name="blue"/>
        </visual>
        <collision>
            <geometry>
                <cylinder radius="0.05" length="0.04"/>
            </geometry>
        </collision>
        <xacro:inertial_cylinder mass="0.1" length="0.04" radius="0.05">
            <origin xyz="0 0 0" rpy="0 0 0"/>
        </xacro:inertial_cylinder>
    </link>

    <gazebo reference="left_wheel">
        <material>Gazebo/Blue</material>
    </gazebo>


    <!-- right front z axis -->
    <joint name="right_front_z_axis_joint" type="revolute">
        <parent link="base_link"/>
        <child link="right_front_z_axis"/>
        <origin xyz="0.2 -0.3 0" rpy="0 0 0" />
        <axis xyz="0 0 1"/>
        <limit lower="-0.9" upper="0.9" effort="1" velocity="5"/>
    </joint>
    <link name="right_front_z_axis">
        <visual>
            <geometry>
                <cylinder radius="0.03" length="0.1"/>
            </geometry>
            <material name="orange"/>
        </visual>
        <collision>
            <geometry>
                <cylinder radius="0.02" length="0.06"/>
            </geometry>
        </collision>
        <xacro:inertial_cylinder mass="0.1" length="0.06" radius="0.02">
            <origin xyz="0 0 0" rpy="0 0 0"/>
        </xacro:inertial_cylinder>
    </link>
    <!-- right front wheel -->

    <joint name="right_front_wheel_joint" type="continuous">
        <parent link="right_front_z_axis"/>
        <child link="right_front_wheel"/>
        <origin xyz="0 -0.06 -0.05" rpy="-${pi/2} 0 0" />
        <axis xyz="0 0 1"/>
    </joint>

    <link name="right_front_wheel">
        <visual>
            <geometry>
                <cylinder radius="0.1" length="0.04"/>
            </geometry>
            <material name="blue"/>
        </visual>
        <collision>
            <geometry>
                <cylinder radius="0.05" length="0.04"/>
            </geometry>
        </collision>
        <xacro:inertial_cylinder mass="0.1" length="0.04" radius="0.05">
            <origin xyz="0 0 0" rpy="0 0 0"/>
        </xacro:inertial_cylinder>
    </link>

    <gazebo reference="right_wheel">
        <material>Gazebo/Blue</material>
    </gazebo>


<!-- right back z axis -->
    <joint name="right_back_z_axis_joint" type="revolute">
        <parent link="base_link"/>
        <child link="right_back_z_axis"/>
        <origin xyz="-0.2 -0.3 0" rpy="0 0 0" />
        <axis xyz="0 0 1"/>
        <limit lower="-0.9" upper="0.9" effort="1" velocity="5"/>
    </joint>
    <link name="right_back_z_axis">
        <visual>
            <geometry>
                <cylinder radius="0.03" length="0.1"/>
            </geometry>
            <material name="orange"/>
        </visual>
        <collision>
            <geometry>
                <cylinder radius="0.02" length="0.06"/>
            </geometry>
        </collision>
        <xacro:inertial_cylinder mass="0.1" length="0.06" radius="0.02">
            <origin xyz="0 0 0" rpy="0 0 0"/>
        </xacro:inertial_cylinder>
    </link>
    <!-- right back wheel -->

    <joint name="right_back_wheel_joint" type="continuous">
        <parent link="right_back_z_axis"/>
        <child link="right_back_wheel"/>
        <origin xyz="0 -0.06 -0.05" rpy="-${pi/2} 0 0" />
        <axis xyz="0 0 1"/>
    </joint>

    <link name="right_back_wheel">
        <visual>
            <geometry>
                <cylinder radius="0.1" length="0.04"/>
            </geometry>
            <material name="blue"/>
        </visual>
        <collision>
            <geometry>
                <cylinder radius="0.05" length="0.04"/>
            </geometry>
        </collision>
        <xacro:inertial_cylinder mass="0.1" length="0.04" radius="0.05">
            <origin xyz="0 0 0" rpy="0 0 0"/>
        </xacro:inertial_cylinder>
    </link>

    <gazebo reference="right_wheel">
        <material>Gazebo/Blue</material>
    </gazebo>



</robot>